<?xml version="1.0" ?>
<!-- =================================================================================== -->
<!-- |    This document was autogenerated by xacro from /home/aochiai/Projects/hsr_oss_ws/src/hsr_description/robots/hsrb4s.urdf.xacro | -->
<!-- |    EDITING THIS FILE BY HAND IS NOT RECOMMENDED                                 | -->
<!-- =================================================================================== -->
<!--
Copyright (c) 2017, Toyota Motor Corporation
All rights reserved.

Redistribution and use in source and binary forms, with or without
modification, are permitted provided that the following conditions are met:

 * Redistributions of source code must retain the above copyright notice,
   this list of conditions and the following disclaimer.
 * Redistributions in binary form must reproduce the above copyright
   notice, this list of conditions and the following disclaimer in the
   documentation and/or other materials provided with the distribution.
 * Neither the name of Toyota Motor Corporation nor the names of its
   contributors may be used to endorse or promote products derived from
   this software without specific prior written permission.

THIS SOFTWARE IS PROVIDED BY THE COPYRIGHT HOLDERS AND CONTRIBUTORS "AS IS"
AND ANY EXPRESS OR IMPLIED WARRANTIES, INCLUDING, BUT NOT LIMITED TO, THE
IMPLIED WARRANTIES OF MERCHANTABILITY AND FITNESS FOR A PARTICULAR PURPOSE
ARE DISCLAIMED. IN NO EVENT SHALL THE COPYRIGHT OWNER OR CONTRIBUTORS BE
LIABLE FOR ANY DIRECT, INDIRECT, INCIDENTAL, SPECIAL, EXEMPLARY, OR
CONSEQUENTIAL DAMAGES (INCLUDING, BUT NOT LIMITED TO, PROCUREMENT OF
SUBSTITUTE GOODS OR SERVICES; LOSS OF USE, DATA, OR PROFITS; OR BUSINESS
INTERRUPTION) HOWEVER CAUSED AND ON ANY THEORY OF LIABILITY, WHETHER IN
CONTRACT, STRICT LIABILITY, OR TORT (INCLUDING NEGLIGENCE OR OTHERWISE)
ARISING IN ANY WAY OUT OF THE USE OF THIS SOFTWARE, EVEN IF ADVISED OF THE
POSSIBILITY OF SUCH DAMAGE.
-->
<robot name="hsrb" xmlns:controller="http://playerstage.sourceforge.net/gazebo/xmlschema/#controller" xmlns:interface="http://playerstage.sourceforge.net/gazebo/xmlschema/#interface" xmlns:sensor="http://playerstage.sourceforge.net/gazebo/xmlschema/#sensor" xmlns:xacro="http://ros.org/wiki/xacro">
  <material name="body_main">
    <color rgba="1.0 0.0 0.0 1.0"/>
  </material>
  <material name="body_sub">
    <color rgba="0.3333 0.3333 0.3333 1.0"/>
  </material>
  <material name="wheel">
    <color rgba="0.2 0.2 0.2 1.0"/>
  </material>
  <material name="black">
    <color rgba="0.1 0.1 0.1 1.0"/>
  </material>
  <material name="white">
    <color rgba="1.0 1.0 1.0 1.0"/>
  </material>
  <material name="green">
    <color rgba="0.0 1.0 0.0 1.0"/>
  </material>
  <material name="blue">
    <color rgba="0.0 0.0 1.0 1.0"/>
  </material>
  <material name="yellow">
    <color rgba="1.0 1.0 0.0 1.0"/>
  </material>
  <material name="tablet">
    <color rgba="0.1 0.1 0.2 1.0"/>
  </material>
  <!--
    ASUS Xtion PRO LIVE
    Specs from:
    http://www.asus.com/Multimedia/Xtion_PRO_LIVE/#specifications
    -->
  <link name="base_footprint">
    <inertial>
      <mass value="0.01"/><!-- 0.0 does not work on pybyllet -->
      <inertia ixx="0.0" ixy="0.0" ixz="0.0" iyy="0.0" iyz="0.0" izz="0.0"/>
    </inertial>
  </link>
  <joint name="base_footprint_joint" type="fixed">
    <parent link="base_footprint"/>
    <child link="base_link"/>
  </joint>
  <link name="base_link">
    <inertial>
      <mass value="50.00"/>
      <!-- use dummy weight to stabilize gazebo move base (real value: 11.017971)-->
      <origin xyz="-0.025978 -0.005498 0.17633"/>
      <inertia ixx="0.3742" ixy="0.000434172172" ixz="0.03088" iyy="0.3436" iyz="0.01775" izz="0.1509"/>
    </inertial>
    <visual>
      <geometry>
        <mesh filename="package://hsr_meshes/meshes/base_v2/base_light.dae"/>
      </geometry>
      <material name="body_sub"/>
    </visual>
    <visual>
      <geometry>
        <mesh filename="package://hsr_meshes/meshes/base_v2/body_light.dae"/>
      </geometry>
      <material name="white"/>
    </visual>
    <visual>
      <geometry>
        <mesh filename="package://hsr_meshes/meshes/base_v2/torso_base.dae"/>
      </geometry>
      <material name="white"/>
    </visual>
    <collision>
      <geometry>
        <mesh filename="package://hsr_meshes/meshes/base_v2/base.stl"/>
      </geometry>
    </collision>
  </link>
  <joint name="base_roll_joint" type="continuous">
    <origin rpy="0.0 0.0 0.0" xyz="0.0 0.0 0.0"/>
    <axis xyz="0.0 0.0 1.0"/>
    <limit effort="34.46" lower="-3.14159265359" upper="3.14159265359" velocity="2.5"/>
    <parent link="base_link"/>
    <child link="base_roll_link"/>
    <dynamics damping="0.7"/>
  </joint>
  <link name="base_roll_link">
    <inertial>
      <origin xyz="-0.01948200 0.00219100 0.07101300"/>
      <mass value="10.239419"/>
      <inertia ixx="0.07671000" ixy="-0.01005000" ixz="0.00174900" iyy="0.09057000" iyz="0.00154900" izz="0.14500000"/>
    </inertial>
  </link>
  <joint name="base_r_drive_wheel_joint" type="continuous">
    <origin rpy="0.0 0.0 0.0" xyz="-0.11 -0.133 0.04"/>
    <axis xyz="0.0 1.0 0.0"/>
    <limit effort="11.067" velocity="20.8"/>
    <parent link="base_roll_link"/>
    <child link="base_r_drive_wheel_link"/>
    <dynamics damping="1.0"/>
  </joint>
  <link name="base_r_drive_wheel_link">
    <visual>
      <origin rpy="1.5707963268 0.0 0.0" xyz="0.0 0.0 0.0"/>
      <geometry>
        <cylinder length="0.03" radius="0.04"/>
      </geometry>
      <material name="wheel"/>
    </visual>
    <collision>
      <origin rpy="1.5707963268 0.0 0.0" xyz="0.0 0.0 0.0"/>
      <geometry>
        <cylinder length="0.03" radius="0.04"/>
      </geometry>
    </collision>
    <inertial>
      <mass value="0.2"/>
      <origin xyz="0 0 0"/>
      <inertia ixx="0.015" ixy="0" ixz="0" iyy="0.015" iyz="0" izz="0.015"/>
    </inertial>
  </link>
  <joint name="base_l_drive_wheel_joint" type="continuous">
    <origin rpy="0.0 0.0 0.0" xyz="-0.11 0.133 0.04"/>
    <axis xyz="0.0 1.0 0.0"/>
    <limit effort="11.067" velocity="20.8"/>
    <parent link="base_roll_link"/>
    <child link="base_l_drive_wheel_link"/>
    <dynamics damping="1.0"/>
  </joint>
  <link name="base_l_drive_wheel_link">
    <visual>
      <origin rpy="1.5707963268 0.0 0.0" xyz="0.0 0.0 0.0"/>
      <geometry>
        <cylinder length="0.03" radius="0.04"/>
      </geometry>
      <material name="wheel"/>
    </visual>
    <collision>
      <origin rpy="1.5707963268 0.0 0.0" xyz="0.0 0.0 0.0"/>
      <geometry>
        <cylinder length="0.03" radius="0.04"/>
      </geometry>
    </collision>
    <inertial>
      <mass value="0.2"/>
      <origin xyz="0 0 0"/>
      <inertia ixx="0.015" ixy="0" ixz="0" iyy="0.015" iyz="0" izz="0.015"/>
    </inertial>
  </link>
  <joint name="base_r_passive_wheel_x_frame_joint" type="continuous">
    <origin rpy="0.0 0.0 0.0" xyz="0.1495                 -0.055                 0.03"/>
    <axis xyz="1.0 0.0 0.0"/>
    <limit effort="1.0" velocity="3.0"/>
    <parent link="base_roll_link"/>
    <child link="base_r_passive_wheel_x_frame"/>
    <dynamics damping="1.0"/>
  </joint>
  <link name="base_r_passive_wheel_x_frame">
    <inertial>
      <mass value="0.2"/>
      <origin xyz="0 0 0"/>
      <inertia ixx="0.015" ixy="0" ixz="0" iyy="0.015" iyz="0" izz="0.015"/>
    </inertial>
  </link>
  <joint name="base_r_passive_wheel_y_frame_joint" type="continuous">
    <axis xyz="0.0 1.0 0.0"/>
    <limit effort="8.85" velocity="10.0"/>
    <parent link="base_r_passive_wheel_x_frame"/>
    <child link="base_r_passive_wheel_y_frame"/>
  </joint>
  <link name="base_r_passive_wheel_y_frame">
    <inertial>
      <mass value="0.2"/>
      <origin xyz="0 0 0"/>
      <inertia ixx="0.015" ixy="0" ixz="0" iyy="0.015" iyz="0" izz="0.015"/>
    </inertial>
  </link>
  <joint name="base_r_passive_wheel_z_joint" type="continuous">
    <axis xyz="0.0 0.0 1.0"/>
    <limit effort="8.85" velocity="10.0"/>
    <parent link="base_r_passive_wheel_y_frame"/>
    <child link="base_r_passive_wheel_z_link"/>
  </joint>
  <link name="base_r_passive_wheel_z_link">
    <visual>
      <geometry>
        <sphere radius="0.03"/>
      </geometry>
      <material name="wheel"/>
    </visual>
    <collision>
      <geometry>
        <sphere radius="0.03"/>
      </geometry>
    </collision>
    <inertial>
      <mass value="0.2"/>
      <origin xyz="0 0 0"/>
      <inertia ixx="0.015" ixy="0" ixz="0" iyy="0.015" iyz="0" izz="0.015"/>
    </inertial>
  </link>
  <joint name="base_l_passive_wheel_x_frame_joint" type="continuous">
    <origin rpy="0.0 0.0 0.0" xyz="0.1495                 0.055                 0.03"/>
    <axis xyz="1.0 0.0 0.0"/>
    <limit effort="1.0" velocity="3.0"/>
    <parent link="base_roll_link"/>
    <child link="base_l_passive_wheel_x_frame"/>
    <dynamics damping="1.0"/>
  </joint>
  <link name="base_l_passive_wheel_x_frame">
    <inertial>
      <mass value="0.2"/>
      <origin xyz="0 0 0"/>
      <inertia ixx="0.015" ixy="0" ixz="0" iyy="0.015" iyz="0" izz="0.015"/>
    </inertial>
  </link>
  <joint name="base_l_passive_wheel_y_frame_joint" type="continuous">
    <axis xyz="0.0 1.0 0.0"/>
    <limit effort="8.85" velocity="10.0"/>
    <parent link="base_l_passive_wheel_x_frame"/>
    <child link="base_l_passive_wheel_y_frame"/>
  </joint>
  <link name="base_l_passive_wheel_y_frame">
    <inertial>
      <mass value="0.2"/>
      <origin xyz="0 0 0"/>
      <inertia ixx="0.015" ixy="0" ixz="0" iyy="0.015" iyz="0" izz="0.015"/>
    </inertial>
  </link>
  <joint name="base_l_passive_wheel_z_joint" type="continuous">
    <axis xyz="0.0 0.0 1.0"/>
    <limit effort="8.85" velocity="10.0"/>
    <parent link="base_l_passive_wheel_y_frame"/>
    <child link="base_l_passive_wheel_z_link"/>
  </joint>
  <link name="base_l_passive_wheel_z_link">
    <visual>
      <geometry>
        <sphere radius="0.03"/>
      </geometry>
      <material name="wheel"/>
    </visual>
    <collision>
      <geometry>
        <sphere radius="0.03"/>
      </geometry>
    </collision>
    <inertial>
      <mass value="0.2"/>
      <origin xyz="0 0 0"/>
      <inertia ixx="0.015" ixy="0" ixz="0" iyy="0.015" iyz="0" izz="0.015"/>
    </inertial>
  </link>
  <joint name="base_range_sensor_joint" type="fixed">
    <origin rpy="0.0 0.0 0.0" xyz="0.1675 0.0 0.1844"/>
    <parent link="base_link"/>
    <child link="base_range_sensor_link"/>
  </joint>
  <link name="base_range_sensor_link">
    <inertial>
      <mass value="0.0"/>
      <inertia ixx="0.0" ixy="0.0" ixz="0.0" iyy="0.0" iyz="0.0" izz="0.0"/>
    </inertial>
    <visual>
      <geometry>
        <mesh filename="package://hsr_meshes/meshes/sensors/laser.dae"/>
      </geometry>
      <material name="body_sub"/>
    </visual>
    <collision>
      <geometry>
        <mesh filename="package://hsr_meshes/meshes/sensors/laser.stl"/>
      </geometry>
    </collision>
  </link>
  <joint name="base_imu_frame_joint" type="fixed">
    <origin rpy="3.14159265359 0.0 0.0" xyz="0.0005 0.1296 0.181"/>
    <parent link="base_link"/>
    <child link="base_imu_frame"/>
  </joint>
  <link name="base_imu_frame">
    <inertial>
      <mass value="0.0"/>
      <inertia ixx="0.0" ixy="0.0" ixz="0.0" iyy="0.0" iyz="0.0" izz="0.0"/>
    </inertial>
  </link>
  <transmission name="base_transmission">
    <type>transmission_interface/SimpleTransmission</type>
    <joint name="base_r_drive_wheel_joint">
      <hardwareInterface>VelocityJointInterface</hardwareInterface>
    </joint>
    <actuator name="base_r_drive_wheel_joint_actuator">
      <hardwareInterface>VelocityJointInterface</hardwareInterface>
      <mechanicalReduction>1</mechanicalReduction>
    </actuator>
  </transmission>
  <transmission name="base_transmission">
    <type>transmission_interface/SimpleTransmission</type>
    <joint name="base_l_drive_wheel_joint">
      <hardwareInterface>VelocityJointInterface</hardwareInterface>
    </joint>
    <actuator name="base_l_drive_wheel_joint_actuator">
      <hardwareInterface>VelocityJointInterface</hardwareInterface>
      <mechanicalReduction>1</mechanicalReduction>
    </actuator>
  </transmission>
  <transmission name="base_roll_joint_transmission">
    <type>transmission_interface/SimpleTransmission</type>
    <joint name="base_roll_joint">
      <hardwareInterface>PositionJointInterface</hardwareInterface>
    </joint>
    <actuator name="base_roll_joint_actuator">
      <hardwareInterface>PositionJointInterface</hardwareInterface>
      <mechanicalReduction>1</mechanicalReduction>
    </actuator>
  </transmission>
  <joint name="torso_lift_joint" type="prismatic">
    <origin rpy="0.0 0.0 0.0" xyz="0.0 0.0 0.752"/>
    <!-- <origin xyz="0.0 0.0 0.752" rpy="0.0 0.0 0.0" /> -->
    <axis xyz="0.0 0.0 1.0"/>
    <limit effort="100.0" lower="0.0" upper="0.345" velocity="0.1"/>
    <parent link="base_link"/>
    <child link="torso_lift_link"/>
    <mimic joint="arm_lift_joint" multiplier="0.5"/>
    <dynamics damping="500.0"/>
  </joint>
  <link name="torso_lift_link">
    <inertial>
      <mass value="3.420779"/>
      <origin xyz="-0.051142 0.003454 -0.2905"/>
      <inertia ixx="0.1045" ixy="-0.000460884801" ixz="0.000101130383" iyy="0.105" iyz="0.002941" izz="0.01284"/>
    </inertial>
    <visual>
      <geometry>
        <mesh filename="package://hsr_meshes/meshes/torso_v0/torso_light.dae"/>
      </geometry>
      <material name="body_sub"/>
    </visual>
    <collision>
      <geometry>
        <mesh filename="package://hsr_meshes/meshes/torso_v0/torso.stl"/>
      </geometry>
    </collision>
  </link>
  <joint name="head_pan_joint" type="revolute">
    <origin rpy="0.0 0.0 0.0" xyz="0.0 0.0 0.0"/>
    <axis xyz="0.0 0.0 1.0"/>
    <limit effort="100.0" lower="-3.14159265359" upper="3.14159265359" velocity="1.0"/>
    <parent link="torso_lift_link"/>
    <child link="head_pan_link"/>
    <dynamics damping="1.0"/>
  </joint>
  <link name="head_pan_link">
    <inertial>
      <mass value="0.571903"/>
      <origin xyz="0.001724 -0.001969 -0.028886"/>
      <inertia ixx="0.0009711421" ixy="0.00006179487" ixz="-0.000113923121" iyy="0.00065335493" iyz="0.000069036305" izz="0.000765202576"/>
    </inertial>
    <visual>
      <geometry>
        <mesh filename="package://hsr_meshes/meshes/head_v1/head_pan.dae"/>
      </geometry>
      <material name="white"/>
    </visual>
    <collision>
      <geometry>
        <mesh filename="package://hsr_meshes/meshes/head_v1/head_pan.stl"/>
      </geometry>
    </collision>
  </link>
  <joint name="head_tilt_joint" type="revolute">
    <origin rpy="0.0 0.0 0.0" xyz="0.02 0.0 0.0"/>
    <axis xyz="0.0 -1.0 0.0"/>
    <limit effort="100.0" lower="-0.78539816339" upper="0.78539816339" velocity="1.0"/>
    <parent link="head_pan_link"/>
    <child link="head_tilt_link"/>
    <dynamics damping="10.0"/>
  </joint>
  <link name="head_tilt_link">
    <inertial>
      <mass value="2.123802"/>
      <origin xyz="-0.055376 -0.002436 0.117733"/>
      <inertia ixx="0.01941" ixy="-0.000138091054" ixz="0.005035" iyy="0.01498" iyz="0.000087492537" izz="0.01167"/>
    </inertial>
    <visual>
      <geometry>
        <mesh filename="package://hsr_meshes/meshes/head_v1/head_upper.dae"/>
      </geometry>
      <material name="body_sub"/>
    </visual>
    <visual>
      <geometry>
        <mesh filename="package://hsr_meshes/meshes/head_v1/head_tilt.dae"/>
      </geometry>
      <material name="body_sub"/>
    </visual>
    <visual>
      <geometry>
        <mesh filename="package://hsr_meshes/meshes/head_v1/tablet_base.dae"/>
      </geometry>
      <material name="white"/>
    </visual>
    <collision>
      <geometry>
        <mesh filename="package://hsr_meshes/meshes/head_v1/head.stl"/>
      </geometry>
    </collision>
    <collision>
      <geometry>
        <mesh filename="package://hsr_meshes/meshes/head_v1/tablet.stl"/>
      </geometry>
    </collision>
  </link>
  <joint name="head_l_stereo_camera_joint" type="fixed">
    <origin rpy="-1.5707963268 0.0 -1.5707963268" xyz="0.02 0.07 0.061"/>
    <parent link="head_tilt_link"/>
    <child link="head_l_stereo_camera_link"/>
  </joint>
  <link name="head_l_stereo_camera_link">
    <inertial>
      <mass value="0.0"/>
      <inertia ixx="0.0" ixy="0.0" ixz="0.0" iyy="0.0" iyz="0.0" izz="0.0"/>
    </inertial>
    <visual>
      <origin rpy="0.0 0.0 0.0" xyz="0 0 0"/>
      <geometry>
        <mesh filename="package://hsr_meshes/meshes/sensors/head_camera.dae"/>
      </geometry>
      <material name="body_sub"/>
    </visual>
  </link>
  <joint name="head_l_stereo_camera_gazebo_frame_joint" type="fixed">
    <origin rpy="1.5707963268 -1.5707963268 0.0" xyz="0 0 0"/>
    <parent link="head_l_stereo_camera_link"/>
    <child link="head_l_stereo_camera_gazebo_frame"/>
  </joint>
  <link name="head_l_stereo_camera_gazebo_frame">
    <inertial>
      <mass value="0.0"/>
      <inertia ixx="0.0" ixy="0.0" ixz="0.0" iyy="0.0" iyz="0.0" izz="0.0"/>
    </inertial>
  </link>
  <joint name="head_r_stereo_camera_joint" type="fixed">
    <origin rpy="-1.5707963268 0.0 -1.5707963268" xyz="0.02 -0.07 0.061"/>
    <parent link="head_tilt_link"/>
    <child link="head_r_stereo_camera_link"/>
  </joint>
  <link name="head_r_stereo_camera_link">
    <inertial>
      <mass value="0.0"/>
      <inertia ixx="0.0" ixy="0.0" ixz="0.0" iyy="0.0" iyz="0.0" izz="0.0"/>
    </inertial>
    <visual>
      <origin rpy="0.0 0.0 0.0" xyz="0 0 0"/>
      <geometry>
        <mesh filename="package://hsr_meshes/meshes/sensors/head_camera.dae"/>
      </geometry>
      <material name="body_sub"/>
    </visual>
  </link>
  <joint name="head_r_stereo_camera_gazebo_frame_joint" type="fixed">
    <origin rpy="1.5707963268 -1.5707963268 0.0" xyz="0 0 0"/>
    <parent link="head_r_stereo_camera_link"/>
    <child link="head_r_stereo_camera_gazebo_frame"/>
  </joint>
  <link name="head_r_stereo_camera_gazebo_frame">
    <inertial>
      <mass value="0.0"/>
      <inertia ixx="0.0" ixy="0.0" ixz="0.0" iyy="0.0" iyz="0.0" izz="0.0"/>
    </inertial>
  </link>
  <joint name="head_center_camera_frame_joint" type="fixed">
    <origin rpy="-1.5707963268 0.0 -1.5707963268" xyz="0.0195 0.0 0.061"/>
    <parent link="head_tilt_link"/>
    <child link="head_center_camera_frame"/>
  </joint>
  <link name="head_center_camera_frame">
    <inertial>
      <mass value="0.0"/>
      <inertia ixx="0.0" ixy="0.0" ixz="0.0" iyy="0.0" iyz="0.0" izz="0.0"/>
    </inertial>
  </link>
  <joint name="head_center_camera_gazebo_frame_joint" type="fixed">
    <origin rpy="1.5707963268 -1.5707963268 0.0" xyz="0 0 0"/>
    <parent link="head_center_camera_frame"/>
    <child link="head_center_camera_gazebo_frame"/>
  </joint>
  <link name="head_center_camera_gazebo_frame">
    <inertial>
      <mass value="0.0"/>
      <inertia ixx="0.0" ixy="0.0" ixz="0.0" iyy="0.0" iyz="0.0" izz="0.0"/>
    </inertial>
  </link>
  <joint name="head_rgbd_sensor_joint" type="fixed">
    <origin rpy="-1.5707963268 0.0 -1.5707963268" xyz="-0.079796 0.022 0.215172"/>
    <parent link="head_tilt_link"/>
    <child link="head_rgbd_sensor_link"/>
  </joint>
  <link name="head_rgbd_sensor_link">
    <inertial>
      <mass value="0.0"/>
      <inertia ixx="0.0" ixy="0.0" ixz="0.0" iyy="0.0" iyz="0.0" izz="0.0"/>
    </inertial>
    <visual>
      <origin rpy="0.0 0.0 0.0" xyz="0 0 0"/>
      <geometry>
        <mesh filename="package://hsr_meshes/meshes/sensors/rgbd_light.dae"/>
      </geometry>
      <material name="body_sub"/>
    </visual>
    <collision>
      <origin rpy="0.0 0.0 0.0" xyz="0 0 0"/>
      <geometry>
        <mesh filename="package://hsr_meshes/meshes/sensors/rgbd.stl"/>
      </geometry>
    </collision>
  </link>
  <joint name="head_rgbd_sensor_gazebo_frame_joint" type="fixed">
    <origin rpy="1.5707963268 -1.5707963268 0.0" xyz="0 0 0"/>
    <parent link="head_rgbd_sensor_link"/>
    <child link="head_rgbd_sensor_gazebo_frame"/>
  </joint>
  
        `
        
  <link name="head_rgbd_sensor_gazebo_frame">
    <inertial>
      <mass value="0.0"/>
      <inertia ixx="0.0" ixy="0.0" ixz="0.0" iyy="0.0" iyz="0.0" izz="0.0"/>
    </inertial>
  </link>
  <transmission name="head_pan_joint_transmission">
    <type>transmission_interface/SimpleTransmission</type>
    <joint name="head_pan_joint">
      <hardwareInterface>PositionJointInterface</hardwareInterface>
    </joint>
    <actuator name="head_pan_joint_actuator">
      <hardwareInterface>PositionJointInterface</hardwareInterface>
      <mechanicalReduction>1</mechanicalReduction>
    </actuator>
  </transmission>
  <transmission name="head_tilt_joint_transmission">
    <type>transmission_interface/SimpleTransmission</type>
    <joint name="head_tilt_joint">
      <hardwareInterface>PositionJointInterface</hardwareInterface>
    </joint>
    <actuator name="head_tilt_joint_actuator">
      <hardwareInterface>PositionJointInterface</hardwareInterface>
      <mechanicalReduction>1</mechanicalReduction>
    </actuator>
  </transmission>
  <joint name="arm_lift_joint" type="prismatic">
    <origin rpy="0.0 0.0 0.0" xyz="0.0 0.0 0.340"/>
    <axis xyz="0.0 0.0 1.0"/>
    <limit effort="100.0" lower="0.0" upper="0.3" velocity="0.2"/>
    <parent link="base_link"/>
    <child link="arm_lift_link"/>
    <dynamics damping="1.0"/>
  </joint>
  <link name="arm_lift_link">
    <inertial>
      <mass value="1.275819"/>
      <origin xyz="0.051549 0.042438 -0.064145"/>
      <inertia ixx="0.004633" ixy="0.000475272668" ixz="-0.002403" iyy="0.008065" iyz="-0.000100268629" izz="0.007672"/>
    </inertial>
    <visual>
      <geometry>
        <mesh filename="package://hsr_meshes/meshes/arm_v0/shoulder.dae"/>
      </geometry>
      <material name="body_sub"/>
    </visual>
    <collision>
      <geometry>
        <mesh filename="package://hsr_meshes/meshes/arm_v0/shoulder.stl"/>
      </geometry>
    </collision>
  </link>
  <joint name="arm_flex_joint" type="revolute">
    <origin rpy="0.0 0.0 0.0" xyz="0.141 0.078 0.0"/>
    <axis xyz="0.0 -1.0 0.0"/>
    <limit effort="100.0" lower="-2.62" upper="0.0" velocity="1.2"/>
    <parent link="arm_lift_link"/>
    <child link="arm_flex_link"/>
    <dynamics damping="1.0"/>
  </joint>
  <link name="arm_flex_link">
    <inertial>
      <mass value="1.339295"/>
      <origin xyz="0.000632 0.006404 0.118529"/>
      <inertia ixx="7.528" ixy="-0.000020284207" ixz="-0.000022947194" iyy="0.007102" iyz="-0.000091796075" izz="0.001552"/>
    </inertial>
    <visual>
      <geometry>
        <mesh filename="package://hsr_meshes/meshes/arm_v0/arm_flex_light.dae"/>
      </geometry>
      <material name="yellow"/>
    </visual>
    <collision>
      <geometry>
        <mesh filename="package://hsr_meshes/meshes/arm_v0/arm_flex.stl"/>
      </geometry>
    </collision>
  </link>
  <joint name="arm_roll_joint" type="revolute">
    <origin rpy="0.0 0.0 0.0" xyz="0.005 0.0 0.345"/>
    <axis xyz="0.0 0.0 1.0"/>
    <limit effort="100.0" lower="-3.14159265359" upper="3.14159265359" velocity="2.0"/>
    <parent link="arm_flex_link"/>
    <child link="arm_roll_link"/>
    <dynamics damping="0.1"/>
  </joint>
  <link name="arm_roll_link">
    <inertial>
      <mass value="0.247936"/>
      <origin xyz="-0.006927 0.002039 -0.064837"/>
      <inertia ixx="0.004267" ixy="-0.000018322199" ixz="0.000017984455" iyy="0.000780923828" iyz="-0.00001392334" izz="0.00412"/>
    </inertial>
    <visual>
      <geometry>
        <mesh filename="package://hsr_meshes/meshes/arm_v0/arm_roll_light.dae"/>
      </geometry>
      <material name="yellow"/>
    </visual>
    <collision>
      <geometry>
        <mesh filename="package://hsr_meshes/meshes/arm_v0/arm_roll.stl"/>
      </geometry>
    </collision>
  </link>
  <transmission name="arm_lift_joint_transmission">
    <type>transmission_interface/SimpleTransmission</type>
    <joint name="arm_lift_joint">
      <hardwareInterface>PositionJointInterface</hardwareInterface>
    </joint>
    <actuator name="arm_lift_joint_actuator">
      <hardwareInterface>PositionJointInterface</hardwareInterface>
      <mechanicalReduction>1</mechanicalReduction>
    </actuator>
  </transmission>
  <transmission name="arm_flex_joint_transmission">
    <type>transmission_interface/SimpleTransmission</type>
    <joint name="arm_flex_joint">
      <hardwareInterface>PositionJointInterface</hardwareInterface>
    </joint>
    <actuator name="arm_flex_joint_actuator">
      <hardwareInterface>PositionJointInterface</hardwareInterface>
      <mechanicalReduction>1</mechanicalReduction>
    </actuator>
  </transmission>
  <transmission name="arm_roll_joint_transmission">
    <type>transmission_interface/SimpleTransmission</type>
    <joint name="arm_roll_joint">
      <hardwareInterface>PositionJointInterface</hardwareInterface>
    </joint>
    <actuator name="arm_roll_joint_actuator">
      <hardwareInterface>PositionJointInterface</hardwareInterface>
      <mechanicalReduction>1</mechanicalReduction>
    </actuator>
  </transmission>
  <joint name="wrist_flex_joint" type="revolute">
    <origin rpy="0.0 0.0 0.0" xyz="0.0 0.0 0.0"/>
    <axis xyz="0.0 -1.0 0.0"/>
    <limit effort="100.0" lower="-1.5707963268" upper="1.5707963268" velocity="1.5"/>
    <parent link="arm_roll_link"/>
    <child link="wrist_flex_link"/>
    <dynamics damping="1.0"/>
  </joint>
  <link name="wrist_flex_link">
    <inertial>
      <mass value="0.681225"/>
      <origin xyz="0.000131 -0.003929 0.00217"/>
      <inertia ixx="0.000074353558" ixy="0.000000494515" ixz="0.000000022937" iyy="0.000038432887" iyz="-0.00000255576" izz="0.000064680918"/>
    </inertial>
    <visual>
      <geometry>
        <mesh filename="package://hsr_meshes/meshes/wrist_v0/wrist_flex.dae"/>
      </geometry>
      <material name="body_sub"/>
    </visual>
    <visual>
      <origin rpy="0.0 0.0 0.0" xyz="0.0 0.0 0.04"/>
      <geometry>
        <cylinder length="0.02" radius="0.017"/>
      </geometry>
      <material name="body_sub"/>
    </visual>
    <collision>
      <origin rpy="0.0 0.0 0.0" xyz="0.0 0.0 0.03"/>
      <geometry>
        <cylinder length="0.04" radius="0.017"/>
      </geometry>
    </collision>
  </link>
  <joint name="wrist_roll_joint" type="revolute">
    <origin rpy="0.0 0.0 0.0" xyz="0.0 0.0 0.0"/>
    <axis xyz="0.0 0.0 1.0"/>
    <limit effort="100.0" lower="-3.14159265359" upper="3.14159265359" velocity="1.5"/>
    <parent link="wrist_flex_link"/>
    <child link="wrist_roll_link"/>
    <dynamics damping="1.0"/>
  </joint>
  <link name="wrist_roll_link">
    <inertial>
      <mass value="0.761692"/>
      <origin xyz="-0.001416 -0.001547 0.081689"/>
      <inertia ixx="0.000805633819" ixy="-0.000014431758" ixz="0.000028204659" iyy="0.000768077165" iyz="0.000022460226" izz="0.000453406611"/>
    </inertial>
    <visual>
      <geometry>
        <mesh filename="package://hsr_meshes/meshes/wrist_v0/wrist_roll.dae"/>
      </geometry>
      <material name="green"/>
    </visual>
    <collision>
      <geometry>
        <mesh filename="package://hsr_meshes/meshes/wrist_v0/wrist_roll.stl"/>
      </geometry>
    </collision>
  </link>
  <joint name="wrist_ft_sensor_frame_joint" type="fixed">
    <origin rpy="3.14159265359 0.0 0.0" xyz="0.0 0.0 0.0735"/>
    <parent link="wrist_roll_link"/>
    <child link="wrist_ft_sensor_frame"/>
  </joint>
  <link name="wrist_ft_sensor_frame">
    <inertial>
      <mass value="0.0"/>
      <inertia ixx="0.0" ixy="0.0" ixz="0.0" iyy="0.0" iyz="0.0" izz="0.0"/>
    </inertial>
  </link>
  <transmission name="wrist_flex_joint_transmission">
    <type>transmission_interface/SimpleTransmission</type>
    <joint name="wrist_flex_joint">
      <hardwareInterface>PositionJointInterface</hardwareInterface>
    </joint>
    <actuator name="wrist_flex_joint_actuator">
      <hardwareInterface>PositionJointInterface</hardwareInterface>
      <mechanicalReduction>1</mechanicalReduction>
    </actuator>
  </transmission>
  <transmission name="wrist_roll_joint_transmission">
    <type>transmission_interface/SimpleTransmission</type>
    <joint name="wrist_roll_joint">
      <hardwareInterface>PositionJointInterface</hardwareInterface>
    </joint>
    <actuator name="wrist_roll_joint_actuator">
      <hardwareInterface>PositionJointInterface</hardwareInterface>
      <mechanicalReduction>1</mechanicalReduction>
    </actuator>
  </transmission>

  <joint name="gripper_extension" type="fixed">
    <axis xyz="1 0 0"/>
    <parent link="wrist_roll_link"/>
    <child link="gripper_pole"/>
    <!-- <limit effort="1000.0" lower="0" upper="0" velocity="0.5"/> -->
    <!-- <origin rpy="0 0 1.57075" xyz="0 0.19 .2"/> -->
    <origin rpy="0 -1.57075 0" xyz="0 0 -0.05"/>
  </joint>

  <link name="gripper_pole">
    <visual>
      <geometry>
        <cylinder length="0.2" radius=".01"/>
      </geometry>
      <origin rpy="0 1.57075 0 " xyz="0.1 0 0"/>
      <material name="Gray">
        <color rgba=".7 .7 .7 1"/>
      </material>
    </visual>
    <collision>
      <geometry>
        <cylinder length="0.2" radius=".01"/>
      </geometry>
      <origin rpy="0 1.57075 0 " xyz="0.1 0 0"/>
    </collision>
    <inertial>
      <mass value="0.05"/>
      <inertia ixx="1.0" ixy="0.0" ixz="0.0" iyy="1.0" iyz="0.0" izz="1.0"/>
    </inertial>
  </link>

  <joint name="left_gripper_joint" type="revolute">
    <axis xyz="0 0 1"/>
    <limit effort="1000.0" lower="0.0" upper="0.548" velocity="0.5"/>
    <origin rpy="0 0 0" xyz="0.2 0.02 0"/>
    <parent link="gripper_pole"/>
    <child link="left_gripper"/>
  </joint>

  <link name="left_gripper">
    <visual>
      <origin rpy="0.0 0 0" xyz="0 0 0"/>
      <geometry>
        <mesh filename="l_finger.stl"/>
      </geometry>
    </visual>
    <collision>
      <geometry>
        <mesh filename="l_finger.stl"/>
      </geometry>
      <origin rpy="0.0 0 0" xyz="0 0 0"/>
    </collision>
    <inertial>
      <mass value="0.05"/>
      <inertia ixx="1.0" ixy="0.0" ixz="0.0" iyy="1.0" iyz="0.0" izz="1.0"/>
    </inertial>
  </link>

  <joint name="left_tip_joint" type="fixed">
    <parent link="left_gripper"/>
    <child link="left_tip"/>
  </joint>

  <link name="left_tip">
    <visual>
      <origin rpy="0.0 0 0" xyz="0.09137 0.00495 0"/>
      <geometry>
        <mesh filename="l_finger_tip.stl"/>
      </geometry>
    </visual>
    <collision>
      <geometry>
        <mesh filename="l_finger_tip.stl"/>
      </geometry>
      <origin rpy="0.0 0 0" xyz="0.09137 0.00495 0"/>
    </collision>
    <inertial>
      <mass value="0.05"/>
      <inertia ixx="1.0" ixy="0.0" ixz="0.0" iyy="1.0" iyz="0.0" izz="1.0"/>
    </inertial>
  </link>

  <joint name="right_gripper_joint" type="revolute">
    <axis xyz="0 0 -1"/>
    <limit effort="1000.0" lower="0.0" upper="0.548" velocity="0.5"/>
    <origin rpy="0 0 0" xyz="0.2 -0.02 0"/>
    <parent link="gripper_pole"/>
    <child link="right_gripper"/>
  </joint>

  <link name="right_gripper">
    <visual>
      <origin rpy="-3.1415 0 0" xyz="0 0 0"/>
      <geometry>
        <mesh filename="l_finger.stl"/>
      </geometry>
    </visual>
    <collision>
      <geometry>
        <mesh filename="l_finger.stl"/>
      </geometry>
      <origin rpy="-3.1415 0 0" xyz="0 0 0"/>
    </collision>
    <inertial>
      <mass value="0.05"/>
      <inertia ixx="1.0" ixy="0.0" ixz="0.0" iyy="1.0" iyz="0.0" izz="1.0"/>
    </inertial>
  </link>

  <joint name="right_tip_joint" type="fixed">
    <parent link="right_gripper"/>
    <child link="right_tip"/>
  </joint>

  <link name="right_tip">
    <visual>
      <origin rpy="-3.1415 0 0" xyz="0.09137 0.00495 0"/>
      <geometry>
        <mesh filename="l_finger_tip.stl"/>
      </geometry>
    </visual>
    <collision>
      <geometry>
        <mesh filename="l_finger_tip.stl"/>
      </geometry>
      <origin rpy="-3.1415 0 0" xyz="0.09137 0.00495 0"/>
    </collision>
    <inertial>
      <mass value="0.05"/>
      <inertia ixx="1.0" ixy="0.0" ixz="0.0" iyy="1.0" iyz="0.0" izz="1.0"/>
    </inertial>
  </link>
</robot>

